<mujoco model="fr3">
  <compiler angle="radian" meshdir="meshes"/>

  <option integrator="implicitfast"/>

  <default>
    <default class="fr3">
      <!-- Overwritten in joints 5, 6, and 7. -->
      <joint damping="0.21" armature="0.195" frictionloss="1.137" actuatorgravcomp="true"/>
      <position inheritrange="1"/>
      <default class="visual">
        <geom type="mesh" group="2" contype="0" conaffinity="0"/>
      </default>
      <default class="collision">
        <geom type="mesh" group="3" mass="0" density="0"/>
      </default>
      <site size="0.001" rgba="0.5 0.5 0.5 0.3" group="4"/>
    </default>

    <default class="2f85">
      <mesh scale="0.001 0.001 0.001"/>
      <general biastype="affine"/>

      <joint axis="1 0 0" actuatorgravcomp="true"/>
      <default class="driver">
        <joint range="0 0.8" armature="0.005" damping="0.1" solimplimit="0.95 0.99 0.001" solreflimit="0.005 1" actuatorgravcomp="true"/>
      </default>
      <default class="follower">
        <joint range="-0.872664 0.872664" armature="0.001" pos="0 -0.018 0.0065" solimplimit="0.95 0.99 0.001" solreflimit="0.005 1" actuatorgravcomp="true"/>
      </default>
      <default class="spring_link">
        <joint range="-0.29670597283 0.8" armature="0.001" stiffness="0.05" springref="2.62" damping="0.00125" actuatorgravcomp="true"/>
      </default>
      <default class="coupler">
        <joint range="-1.57 0" armature="0.001" solimplimit="0.95 0.99 0.001" solreflimit="0.005 1" actuatorgravcomp="true"/>
      </default>

      <default class="2f85_visual">
        <geom type="mesh" contype="0" conaffinity="0" group="2"/>
      </default>
      <default class="2f85_collision">
        <geom type="mesh" group="3"/>
        <default class="pad_box1">
          <geom mass="0" type="box" pos="0 -0.0026 0.028125" size="0.011 0.004 0.009375" friction="0.7"
            solimp="0.95 0.99 0.001" solref="0.004 1" priority="1" rgba="0.55 0.55 0.55 1"/>
        </default>
        <default class="pad_box2">
          <geom mass="0" type="box" pos="0 -0.0026 0.009375" size="0.011 0.004 0.009375" friction="0.6"
            solimp="0.95 0.99 0.001" solref="0.004 1" priority="1" rgba="0.45 0.45 0.45 1"/>
        </default>
      </default>
    </default>
  </default>

  <asset>
    <material name="black" rgba=".2 .2 .2 1"/>
    <material name="white" rgba="1 1 1 1"/>
    <material name="red" rgba="1 0.072272 0.039546 1"/>
    <material name="gray" rgba="0.863156 0.863156 0.863157 1"/>
    <material name="metal" rgba="0.58 0.58 0.58 1"/>
    <material name="silicone" rgba="0.1882 0.1882 0.1882 1"/>
    <material name="button_green" rgba="0.102241 0.571125 0.102242 1"/>
    <material name="button_red" rgba="0.520996 0.008023 0.013702 1"/>
    <material name="button_blue" rgba="0.024157 0.445201 0.737911 1"/>

    <texture type="2d" name="groundplane" builtin="checker" mark="edge" rgb1="0.2 0.3 0.4" rgb2="0.1 0.2 0.3"
      markrgb="0.8 0.8 0.8" width="300" height="300"/>
    <material name="groundplane" texture="groundplane" texuniform="true" texrepeat="5 5" reflectance="0.2"/>

    <mesh file="link0_0.obj"/>
    <mesh file="link0_1.obj"/>
    <mesh file="link0_2.obj"/>
    <mesh file="link0_3.obj"/>
    <mesh file="link0_4.obj"/>
    <mesh file="link0_5.obj"/>
    <mesh file="link0_6.obj"/>
    <mesh file="link1.obj"/>
    <mesh file="link2.obj"/>
    <mesh file="link3_0.obj"/>
    <mesh file="link3_1.obj"/>
    <mesh file="link4_0.obj"/>
    <mesh file="link4_1.obj"/>
    <mesh file="link5_0.obj"/>
    <mesh file="link5_1.obj"/>
    <mesh file="link5_2.obj"/>
    <mesh file="link6_0.obj"/>
    <mesh file="link6_1.obj"/>
    <mesh file="link6_2.obj"/>
    <mesh file="link6_3.obj"/>
    <mesh file="link6_4.obj"/>
    <mesh file="link6_5.obj"/>
    <mesh file="link6_6.obj"/>
    <mesh file="link6_7.obj"/>
    <mesh file="link7_0.obj"/>
    <mesh file="link7_1.obj"/>
    <mesh file="link7_2.obj"/>
    <mesh file="link7_3.obj"/>

    <mesh name="link0_coll" file="link0.stl"/>
    <mesh name="link1_coll" file="link1.stl"/>
    <mesh name="link2_coll" file="link2.stl"/>
    <mesh name="link3_coll" file="link3.stl"/>
    <mesh name="link4_coll" file="link4.stl"/>
    <mesh name="link5_coll" file="link5.stl"/>
    <mesh name="link6_coll" file="link6.stl"/>
    <mesh name="link7_coll" file="link7.stl"/>

    <mesh class="2f85" file="base_mount.stl"/>
    <mesh class="2f85" file="base.stl"/>
    <mesh class="2f85" file="driver.stl"/>
    <mesh class="2f85" file="coupler.stl"/>
    <mesh class="2f85" file="follower.stl"/>
    <mesh class="2f85" file="pad.stl"/>
    <mesh class="2f85" file="silicone_pad.stl"/>
    <mesh class="2f85" file="spring_link.stl"/>
  </asset>

  <worldbody>
    <body name="fr3_link0" childclass="fr3" pos="0 0 0" gravcomp="1">
        <geom mesh="link0_0" material="black" class="visual"/>
        <geom mesh="link0_1" material="white" class="visual"/>
        <geom mesh="link0_2" material="white" class="visual"/>
        <geom mesh="link0_3" material="white" class="visual"/>
        <geom mesh="link0_4" material="white" class="visual"/>
        <geom mesh="link0_5" material="red" class="visual"/>
        <geom mesh="link0_6" material="black" class="visual"/>
        <geom name="fr3_link0_collision" mesh="link0_coll" class="collision"/>
        <body name="fr3_link1" pos="0 0 0.333" gravcomp="1">
          <inertial pos="4.128e-07 -0.0181251 -0.0386036" quat="0.998098 -0.0605364 0.00380499 0.0110109" mass="2.92747"
            diaginertia="0.0239286 0.0227246 0.00610634"/>
          <joint name="fr3_joint1" axis="0 0 1" range="-2.7437 2.7437" actuatorfrcrange="-87 87" actuatorgravcomp="true"/>
          <geom name="fr3_link1_collision" class="collision" mesh="link1_coll"/>
          <geom material="white" mesh="link1" class="visual"/>
          <body name="fr3_link2" quat="1 -1 0 0" gravcomp="1">
            <inertial pos="0.00318289 -0.0743222 0.00881461" quat="0.502599 0.584437 -0.465998 0.434366" mass="2.93554"
              diaginertia="0.0629567 0.0411924 0.0246371"/>
            <joint name="fr3_joint2" axis="0 0 1" range="-1.7837 1.7837" actuatorfrcrange="-87 87" actuatorgravcomp="true"/>
            <geom material="white" mesh="link2" class="visual"/>
            <geom name="fr3_link2_collision" class="collision" mesh="link2_coll"/>
            <body name="fr3_link3" pos="0 -0.316 0" quat="1 1 0 0" gravcomp="1">
              <inertial pos="0.0407016 -0.00482006 -0.0289731" quat="0.921025 -0.244161 0.155272 0.260745" mass="2.2449"
                diaginertia="0.0267409 0.0189869 0.0171587"/>
              <joint name="fr3_joint3" axis="0 0 1" range="-2.9007 2.9007" actuatorfrcrange="-87 87" actuatorgravcomp="true"/>
              <geom mesh="link3_0" material="white" class="visual"/>
              <geom mesh="link3_1" material="black" class="visual"/>
              <geom name="fr3_link3_collision" class="collision" mesh="link3_coll"/>
              <body name="fr3_link4" pos="0.0825 0 0" quat="1 1 0 0" gravcomp="1">
                <inertial pos="-0.0459101 0.0630493 -0.00851879" quat="0.438018 0.803311 0.00937812 0.403414"
                  mass="2.6156" diaginertia="0.05139 0.0372717 0.0160047"/>
                <joint name="fr3_joint4" axis="0 0 1" range="-3.0421 -0.1518" actuatorfrcrange="-87 87" actuatorgravcomp="true"/>
                <geom mesh="link4_0" material="white" class="visual"/>
                <geom mesh="link4_1" material="black" class="visual"/>
                <geom name="fr3_link4_collision" class="collision" mesh="link4_coll"/>
                <body name="fr3_link5" pos="-0.0825 0.384 0" quat="1 -1 0 0" gravcomp="1">
                  <inertial pos="-0.00160396 0.0292536 -0.0972966" quat="0.919031 0.125604 0.0751531 -0.366003"
                    mass="2.32712" diaginertia="0.0579335 0.0449144 0.0130634"/>
                  <joint name="fr3_joint5" axis="0 0 1" range="-2.8065 2.8065" actuatorfrcrange="-12 12"
                    armature="0.074" frictionloss="0.763" actuatorgravcomp="true"/>
                  <geom mesh="link5_0" material="white" class="visual"/>
                  <geom mesh="link5_1" material="white" class="visual"/>
                  <geom mesh="link5_2" material="black" class="visual"/>
                  <geom name="fr3_link5_collision" class="collision" mesh="link5_coll"/>
                  <body name="fr3_link6" quat="1 1 0 0" gravcomp="1">
                    <inertial pos="0.0597131 -0.0410295 -0.0101693" quat="0.621301 0.552665 0.510011 0.220081"
                      mass="1.81704" diaginertia="0.0175039 0.0161123 0.00193529"/>
                    <joint name="fr3_joint6" axis="0 0 1" range="0.5445 4.5169" actuatorfrcrange="-12 12"
                      armature="0.074" frictionloss="0.44" actuatorgravcomp="true"/>
                    <geom mesh="link6_0" material="button_green" class="visual"/>
                    <geom mesh="link6_1" material="white" class="visual"/>
                    <geom mesh="link6_2" material="white" class="visual"/>
                    <geom mesh="link6_3" material="gray" class="visual"/>
                    <geom mesh="link6_4" material="button_red" class="visual"/>
                    <geom mesh="link6_5" material="white" class="visual"/>
                    <geom mesh="link6_6" material="black" class="visual"/>
                    <geom mesh="link6_7" material="button_blue" class="visual"/>
                    <geom name="fr3_link6_collision" class="collision" mesh="link6_coll"/>
                    <body name="fr3_link7" pos="0.088 0 0" quat="1 1 0 0" gravcomp="1">
                      <inertial pos="0.00452258 0.00862619 -0.0161633" quat="0.727579 0.0978688 -0.24906 0.63168"
                        mass="0.627143" diaginertia="0.000223836 0.000223642 5.64132e-07"/>
                      <joint name="fr3_joint7" axis="0 0 1" range="-3.0159 3.0159" actuatorfrcrange="-12 12"
                        armature="0.074" frictionloss="0.248" actuatorgravcomp="true"/>
                      <geom mesh="link7_0" material="black" class="visual"/>
                      <geom mesh="link7_1" material="white" class="visual"/>
                      <geom mesh="link7_2" material="white" class="visual"/>
                      <geom mesh="link7_3" material="black" class="visual"/>
                      <geom name="fr3_link7_collision" class="collision" mesh="link7_coll"/>
                      <site name="attachment_site" pos="0 0 0.107"/>
                      <include file="2f85.xml"></include>
                    </body>
                  </body>
                </body>
              </body>
            </body>
          </body>
        </body>
    </body>
  </worldbody>

  <actuator>
    <position class="fr3" name="fr3_joint1" joint="fr3_joint1" kp="400" kv="40" />
    <position class="fr3" name="fr3_joint2" joint="fr3_joint2" kp="300" kv="60" />
    <position class="fr3" name="fr3_joint3" joint="fr3_joint3" kp="500" kv="50" />
    <position class="fr3" name="fr3_joint4" joint="fr3_joint4" kp="250" kv="50" />
    <position class="fr3" name="fr3_joint5" joint="fr3_joint5" kp="350" kv="30" />
    <position class="fr3" name="fr3_joint6" joint="fr3_joint6" kp="250" kv="20" />
    <position class="fr3" name="fr3_joint7" joint="fr3_joint7" kp="100" kv="10" />

    <!-- <position class="fr3" name="fr3_joint1" joint="fr3_joint1" kp="4500" kv="450" />
    <position class="fr3" name="fr3_joint2" joint="fr3_joint2" kp="4500" kv="450" />
    <position class="fr3" name="fr3_joint3" joint="fr3_joint3" kp="3500" kv="350" />
    <position class="fr3" name="fr3_joint4" joint="fr3_joint4" kp="3500" kv="350" />
    <position class="fr3" name="fr3_joint5" joint="fr3_joint5" kp="2000" kv="200" />
    <position class="fr3" name="fr3_joint6" joint="fr3_joint6" kp="2000" kv="200" />
    <position class="fr3" name="fr3_joint7" joint="fr3_joint7" kp="2000" kv="200" /> -->
    
    <general class="2f85" name="fingers_actuator" tendon="split" forcerange="-5 5" ctrlrange="0 1"
      gainprm="5.0 0 0" biasprm="0 -5.0 -0.01"/>
  </actuator>

  <!--
    This adds stability to the model by having a tendon that distributes the forces between both
    joints, such that the equality constraint doesn't have to do that much work in order to equalize
    both joints. Since both joints share the same sign, we split the force between both equally by
    setting coef=0.5
  -->
  <tendon>
    <fixed name="split">
      <joint joint="right_driver_joint" coef="0.5"/>
      <joint joint="left_driver_joint" coef="0.5"/>
    </fixed>
  </tendon>

  <equality>
    <connect anchor="0 0 0" body1="right_follower" body2="right_coupler" solimp="0.95 0.99 0.001" solref="0.005 1"/>
    <connect anchor="0 0 0" body1="left_follower" body2="left_coupler" solimp="0.95 0.99 0.001" solref="0.005 1"/>
    <joint joint1="right_driver_joint" joint2="left_driver_joint" polycoef="0 1 0 0 0" solimp="0.95 0.99 0.001"
      solref="0.005 1"/>
  </equality>

  <contact>
    <exclude body1="fr3_link0" body2="fr3_link1"/>
    <exclude body1="2f85_base" body2="left_driver"/>
    <exclude body1="2f85_base" body2="right_driver"/>
    <exclude body1="2f85_base" body2="left_spring_link"/>
    <exclude body1="2f85_base" body2="right_spring_link"/>
    <exclude body1="right_coupler" body2="right_follower"/>
    <exclude body1="left_coupler" body2="left_follower"/>
  </contact>

  <!--
    The general actuator below is a customized position actuator (with some damping) where
    gainprm[0] != kp (see http://mujoco.org/book/modeling.html#position).
    The reason why gainprm[0] != kp is because the control input range has to be re-scaled to
    [0, 255]. The joint range is currently set at [0, 0.8], the control range is [0, 255] and
    kp = 100. Tau = Kp * scale * control_input - Kp * error, max(Kp * scale * control_input) = 0.8,
    hence scale = 0.8 * 100 / 255
  -->
  <!-- <actuator>
    <general class="2f85" name="fingers_actuator" tendon="split" forcerange="-5 5" ctrlrange="0 255"
      gainprm="0.3137255 0 0" biasprm="0 -100 -10"/>
  </actuator> -->

  <keyframe>
    <key name="home" qpos="0 0 0 -1.57079 0 1.57079 -0.7853" ctrl="0 0 0 -1.57079 0 1.57079 -0.7853 0"/>
  </keyframe>
</mujoco>
